<?xml version="1.0" encoding="utf-8"?>

<robot
  name="7DOFArm.SLDASM">
  <link
    name="base_link">
    <inertial>
      <origin
        xyz="-8.34818179536046E-06 0.00557610441589056 0.0211254794790421"
        rpy="0 0 0" />
      <mass
        value="0.195948164313462" />
      <inertia
        ixx="0.000268946195921621"
        ixy="1.37361739472986E-08"
        ixz="6.7375337150921E-09"
        iyy="5.4818408490663E-05"
        iyz="-5.13728177875137E-06"
        izz="0.00028132542818711" />
    </inertial>
    <visual>
      <origin
        xyz="0 0 0"
        rpy="0 0 0" />
      <geometry>
        <mesh
          filename="package://7DOFArm.SLDASM/meshes/base_link.STL" />
      </geometry>
      <material
        name="">
        <color
          rgba="0.752941176470588 0.752941176470588 0.752941176470588 1" />
      </material>
    </visual>
    <collision>
      <origin
        xyz="0 0 0"
        rpy="0 0 0" />
      <geometry>
        <mesh
          filename="package://7DOFArm.SLDASM/meshes/base_link.STL" />
      </geometry>
    </collision>
  </link>
  <link
    name="Link2">
    <inertial>
      <origin
        xyz="4.80530943714782E-05 -0.00152789147324323 0.0199929397826317"
        rpy="0 0 0" />
      <mass
        value="0.055389475138638" />
      <inertia
        ixx="1.01366009285935E-05"
        ixy="1.55656523407097E-10"
        ixz="-8.86193755831385E-10"
        iyy="1.47698235348992E-05"
        iyz="2.02524178578314E-08"
        izz="1.46211245395671E-05" />
    </inertial>
    <visual>
      <origin
        xyz="0 0 0"
        rpy="0 0 0" />
      <geometry>
        <mesh
          filename="package://7DOFArm.SLDASM/meshes/Link2.STL" />
      </geometry>
      <material
        name="">
        <color
          rgba="0.752941176470588 0.752941176470588 0.752941176470588 1" />
      </material>
    </visual>
    <collision>
      <origin
        xyz="0 0 0"
        rpy="0 0 0" />
      <geometry>
        <mesh
          filename="package://7DOFArm.SLDASM/meshes/Link2.STL" />
      </geometry>
    </collision>
  </link>
  <joint
    name="Joint0"
    type="continuous">
    <origin
      xyz="0 0.0395 0.044"
      rpy="0 0 -0.0063255066818594" />
    <parent
      link="base_link" />
    <child
      link="Link2" />
    <axis
      xyz="0 0 1" />
  </joint>
  <link
    name="Link3">
    <inertial>
      <origin
        xyz="1.20829453213733E-14 8.37104158513124E-06 0.101999999999929"
        rpy="0 0 0" />
      <mass
        value="0.390826093219989" />
      <inertia
        ixx="0.000559492053280385"
        ixy="5.98929161948754E-16"
        ixz="1.13812165974477E-05"
        iyy="0.000534406308901428"
        iyz="-1.76981104736603E-15"
        izz="0.000109181488336245" />
    </inertial>
    <visual>
      <origin
        xyz="0 0 0"
        rpy="0 0 0" />
      <geometry>
        <mesh
          filename="package://7DOFArm.SLDASM/meshes/Link3.STL" />
      </geometry>
      <material
        name="">
        <color
          rgba="0.752941176470588 0.752941176470588 0.752941176470588 1" />
      </material>
    </visual>
    <collision>
      <origin
        xyz="0 0 0"
        rpy="0 0 0" />
      <geometry>
        <mesh
          filename="package://7DOFArm.SLDASM/meshes/Link3.STL" />
      </geometry>
    </collision>
  </link>
  <joint
    name="Joint1"
    type="continuous">
    <origin
      xyz="0 -0.0030000000000001 0.0450000000000002"
      rpy="1.06447174148775 0 0" />
    <parent
      link="Link2" />
    <child
      link="Link3" />
    <axis
      xyz="1 0 0" />
  </joint>
  <link
    name="Link4">
    <inertial>
      <origin
        xyz="-4.80530943716832E-05 0.00147210852675678 0.0250070602173683"
        rpy="0 0 0" />
      <mass
        value="0.055389475138638" />
      <inertia
        ixx="1.01366009285935E-05"
        ixy="-1.55656523405905E-10"
        ixz="-8.86193755831224E-10"
        iyy="1.47698235348991E-05"
        iyz="-2.02524178578319E-08"
        izz="1.46211245395671E-05" />
    </inertial>
    <visual>
      <origin
        xyz="0 0 0"
        rpy="0 0 0" />
      <geometry>
        <mesh
          filename="package://7DOFArm.SLDASM/meshes/Link4.STL" />
      </geometry>
      <material
        name="">
        <color
          rgba="0.752941176470588 0.752941176470588 0.752941176470588 1" />
      </material>
    </visual>
    <collision>
      <origin
        xyz="0 0 0"
        rpy="0 0 0" />
      <geometry>
        <mesh
          filename="package://7DOFArm.SLDASM/meshes/Link4.STL" />
      </geometry>
    </collision>
  </link>
  <joint
    name="Joint2"
    type="continuous">
    <origin
      xyz="0 0 0.204"
      rpy="-0.982875993996659 0 0" />
    <parent
      link="Link3" />
    <child
      link="Link4" />
    <axis
      xyz="-1 0 0" />
  </joint>
  <link
    name="Link5">
    <inertial>
      <origin
        xyz="-8.3481816847775E-06 0.0785246875304838 0.050965409786628"
        rpy="0 0 0" />
      <mass
        value="0.391896328746283" />
      <inertia
        ixx="0.000537892391856797"
        ixy="-6.9986418036451E-09"
        ixz="-2.04737067713958E-08"
        iyy="0.00033614383668443"
        iyz="-4.93463155737849E-16"
        izz="0.000336143836684597" />
    </inertial>
    <visual>
      <origin
        xyz="0 0 0"
        rpy="0 0 0" />
      <geometry>
        <mesh
          filename="package://7DOFArm.SLDASM/meshes/Link5.STL" />
      </geometry>
      <material
        name="">
        <color
          rgba="0.752941176470588 0.752941176470588 0.752941176470588 1" />
      </material>
    </visual>
    <collision>
      <origin
        xyz="0 0 0"
        rpy="0 0 0" />
      <geometry>
        <mesh
          filename="package://7DOFArm.SLDASM/meshes/Link5.STL" />
      </geometry>
    </collision>
  </link>
  <joint
    name="Joint3"
    type="continuous">
    <origin
      xyz="0 0.00300000000000002 0.0339337982667513"
      rpy="0 0 -0.0373408822518601" />
    <parent
      link="Link4" />
    <child
      link="Link5" />
    <axis
      xyz="0 0 -1" />
  </joint>
  <link
    name="Link6">
    <inertial>
      <origin
        xyz="4.80530943693545E-05 0.0259429985826935 0.00152789147324323"
        rpy="0 0 0" />
      <mass
        value="0.0553894751386379" />
      <inertia
        ixx="1.01366009285935E-05"
        ixy="-8.86193755830644E-10"
        ixz="-1.55656523403457E-10"
        iyy="1.46211245395671E-05"
        iyz="-2.02524178578316E-08"
        izz="1.47698235348991E-05" />
    </inertial>
    <visual>
      <origin
        xyz="0 0 0"
        rpy="0 0 0" />
      <geometry>
        <mesh
          filename="package://7DOFArm.SLDASM/meshes/Link6.STL" />
      </geometry>
      <material
        name="">
        <color
          rgba="0.752941176470588 0.752941176470588 0.752941176470588 1" />
      </material>
    </visual>
    <collision>
      <origin
        xyz="0 0 0"
        rpy="0 0 0" />
      <geometry>
        <mesh
          filename="package://7DOFArm.SLDASM/meshes/Link6.STL" />
      </geometry>
    </collision>
  </link>
  <joint
    name="Joint4"
    type="continuous">
    <origin
      xyz="0 0.140049941199938 0.0340662017332484"
      rpy="0 0.0178678459046033 0" />
    <parent
      link="Link5" />
    <child
      link="Link6" />
    <axis
      xyz="0 1 0" />
  </joint>
  <link
    name="Link7">
    <inertial>
      <origin
        xyz="0.000917901933196848 0.0786320562659005 0.0169893200790058"
        rpy="0 0 0" />
      <mass
        value="0.391361210934714" />
      <inertia
        ixx="0.000548692222565865"
        ixy="-5.68387076435446E-06"
        ixz="-6.99864073104178E-09"
        iyy="0.000335916172357848"
        iyz="5.15101791261378E-06"
        izz="0.000322021562938926" />
    </inertial>
    <visual>
      <origin
        xyz="0 0 0"
        rpy="0 0 0" />
      <geometry>
        <mesh
          filename="package://7DOFArm.SLDASM/meshes/Link7.STL" />
      </geometry>
      <material
        name="">
        <color
          rgba="0.752941176470588 0.752941176470588 0.752941176470588 1" />
      </material>
    </visual>
    <collision>
      <origin
        xyz="0 0 0"
        rpy="0 0 0" />
      <geometry>
        <mesh
          filename="package://7DOFArm.SLDASM/meshes/Link7.STL" />
      </geometry>
    </collision>
  </link>
  <joint
    name="Joint5"
    type="continuous">
    <origin
      xyz="0 0.0509500588000616 0.00300000000000006"
      rpy="-0.00877434456653207 0 0" />
    <parent
      link="Link6" />
    <child
      link="Link7" />
    <axis
      xyz="-1 0 0" />
  </joint>
  <link
    name="EndEffector">
    <inertial>
      <origin
        xyz="-0.000652115884172889 0.16606767934612 0.00179570680438307"
        rpy="0 0 0" />
      <mass
        value="0.533035537217521" />
      <inertia
        ixx="0.000828026554879931"
        ixy="6.06699838054548E-07"
        ixz="-1.92693806277969E-05"
        iyy="0.000472118631073817"
        iyz="-1.69711560363912E-06"
        izz="0.000873966442795746" />
    </inertial>
    <visual>
      <origin
        xyz="0 0 0"
        rpy="0 0 0" />
      <geometry>
        <mesh
          filename="package://7DOFArm.SLDASM/meshes/EndEffector.STL" />
      </geometry>
      <material
        name="">
        <color
          rgba="0.752941176470588 0.752941176470588 0.752941176470588 1" />
      </material>
    </visual>
    <collision>
      <origin
        xyz="0 0 0"
        rpy="0 0 0" />
      <geometry>
        <mesh
          filename="package://7DOFArm.SLDASM/meshes/EndEffector.STL" />
      </geometry>
    </collision>
  </link>
  <joint
    name="Joint6"
    type="continuous">
    <origin
      xyz="0.000999999999997949 0.124829928909805 0"
      rpy="0 0 0" />
    <parent
      link="Link7" />
    <child
      link="EndEffector" />
    <axis
      xyz="0 -1 0" />
  </joint>
</robot>