<?xml version="1.0" encoding="utf-8"?>
<!-- This URDF was automatically created by SolidWorks to URDF Exporter! Originally created by Stephen Brawner (brawner@gmail.com) 
     Commit Version: 1.6.0-1-g15f4949  Build Version: 1.6.7594.29634
     For more information, please see http://wiki.ros.org/sw_urdf_exporter -->
<robot
  name="5DOFArm">
  <link
    name="Motor1">
    <inertial>
      <origin
        xyz="-8.3481817953826E-06 -0.0339238955841094 0.0211254794790421"
        rpy="0 0 0" />
      <mass
        value="0.195948164313462" />
      <inertia
        ixx="0.000268946195921621"
        ixy="1.37361739472899E-08"
        ixz="6.73753371510302E-09"
        iyy="5.4818408490663E-05"
        iyz="-5.13728177875135E-06"
        izz="0.00028132542818711" />
    </inertial>
    <visual>
      <origin
        xyz="0 0 0"
        rpy="0 0 0" />
      <geometry>
        <mesh
          filename="package://5DOFArm/meshes/Motor1.STL" />
      </geometry>
      <material
        name="">
        <color
          rgba="0.752941176470588 0.752941176470588 0.752941176470588 1" />
      </material>
    </visual>
    <collision>
      <origin
        xyz="0 0 0"
        rpy="0 0 0" />
      <geometry>
        <mesh
          filename="package://5DOFArm/meshes/Motor1.STL" />
      </geometry>
    </collision>
  </link>
  <link
    name="ConnectingJointA">
    <inertial>
      <origin
        xyz="-4.80530943714544E-05 0.00152789147324323 0.0199929397826317"
        rpy="0 0 0" />
      <mass
        value="0.0553894751386379" />
      <inertia
        ixx="1.01366009285935E-05"
        ixy="1.55656523406104E-10"
        ixz="8.86193755830673E-10"
        iyy="1.47698235348991E-05"
        iyz="-2.02524178578313E-08"
        izz="1.46211245395671E-05" />
    </inertial>
    <visual>
      <origin
        xyz="0 0 0"
        rpy="0 0 0" />
      <geometry>
        <mesh
          filename="package://5DOFArm/meshes/ConnectingJointA.STL" />
      </geometry>
      <material
        name="">
        <color
          rgba="0.752941176470588 0.752941176470588 0.752941176470588 1" />
      </material>
    </visual>
    <collision>
      <origin
        xyz="0 0 0"
        rpy="0 0 0" />
      <geometry>
        <mesh
          filename="package://5DOFArm/meshes/ConnectingJointA.STL" />
      </geometry>
    </collision>
  </link>
  <joint
    name="ConnectingJoint1"
    type="continuous">
    <origin
      xyz="0 0 0.044"
      rpy="0 0 0.066433" />
    <parent
      link="Motor1" />
    <child
      link="ConnectingJointA" />
    <axis
      xyz="0 0 1" />
  </joint>
  <link
    name="Motor2">
    <inertial>
      <origin
        xyz="0.000843968187271227 -0.000718332252681683 0.0340099376338211"
        rpy="0 0 0" />
      <mass
        value="0.195408857598652" />
      <inertia
        ixx="0.000279745738336469"
        ixy="1.1202981933852E-07"
        ixz="-5.68950943432409E-06"
        iyy="0.00026711095979096"
        iyz="4.42263757751427E-06"
        izz="5.46826216554872E-05" />
    </inertial>
    <visual>
      <origin
        xyz="0 0 0"
        rpy="0 0 0" />
      <geometry>
        <mesh
          filename="package://5DOFArm/meshes/Motor2.STL" />
      </geometry>
      <material
        name="">
        <color
          rgba="0.752941176470588 0.752941176470588 0.752941176470588 1" />
      </material>
    </visual>
    <collision>
      <origin
        xyz="0 0 0"
        rpy="0 0 0" />
      <geometry>
        <mesh
          filename="package://5DOFArm/meshes/Motor2.STL" />
      </geometry>
    </collision>
  </link>
  <joint
    name="ConnectingJointA2"
    type="continuous">
    <origin
      xyz="0 0.003 0.045"
      rpy="0 0 0" />
    <parent
      link="ConnectingJointA" />
    <child
      link="Motor2" />
    <axis
      xyz="-1 0 0" />
  </joint>
  <link
    name="Motor3">
    <inertial>
      <origin
        xyz="0.00335886157392549 0.137291968696234 0.0950916743893828"
        rpy="0 0 0" />
      <mass
        value="0.19540885759776" />
      <inertia
        ixx="0.000279745738337905"
        ixy="6.73751546776728E-09"
        ixz="-5.69060830572569E-06"
        iyy="0.00026720299583469"
        iyz="1.37361711252987E-08"
        izz="5.45905856134453E-05" />
    </inertial>
    <visual>
      <origin
        xyz="0 0 0"
        rpy="0 0 0" />
      <geometry>
        <mesh
          filename="package://5DOFArm/meshes/Motor3.STL" />
      </geometry>
      <material
        name="">
        <color
          rgba="0.752941176470588 0.752941176470588 0.752941176470588 1" />
      </material>
    </visual>
    <collision>
      <origin
        xyz="0 0 0"
        rpy="0 0 0" />
      <geometry>
        <mesh
          filename="package://5DOFArm/meshes/Motor3.STL" />
      </geometry>
    </collision>
  </link>
  <joint
    name="Motor2to3Fixed"
    type="fixed">
    <origin
      xyz="-0.0042028 -0.13883 0.072009"
      rpy="0.020872 0 0" />
    <parent
      link="Motor2" />
    <child
      link="Motor3" />
    <axis
      xyz="0 0 0" />
  </joint>
  <link
    name="ConnectingJointB">
    <inertial>
      <origin
        xyz="0.00425088285560192 -0.00160430277859039 0.0249989275134803"
        rpy="0 0 0" />
      <mass
        value="0.0553894751386379" />
      <inertia
        ixx="1.01366009285935E-05"
        ixy="-1.60339742804096E-10"
        ixz="8.85358398061052E-10"
        iyy="1.47696052281304E-05"
        iyz="2.10374610736327E-08"
        izz="1.46213428463358E-05" />
    </inertial>
    <visual>
      <origin
        xyz="0 0 0"
        rpy="0 0 0" />
      <geometry>
        <mesh
          filename="package://5DOFArm/meshes/ConnectingJointB.STL" />
      </geometry>
      <material
        name="">
        <color
          rgba="0.752941176470588 0.752941176470588 0.752941176470588 1" />
      </material>
    </visual>
    <collision>
      <origin
        xyz="0 0 0"
        rpy="0 0 0" />
      <geometry>
        <mesh
          filename="package://5DOFArm/meshes/ConnectingJointB.STL" />
      </geometry>
    </collision>
  </link>
  <joint
    name="ConnectingJointB1"
    type="continuous">
    <origin
      xyz="0 0.1373 0.12911"
      rpy="0 0 0" />
    <parent
      link="Motor3" />
    <child
      link="ConnectingJointB" />
    <axis
      xyz="1 0 0" />
  </joint>
  <link
    name="Motor4">
    <inertial>
      <origin
        xyz="-0.00113218214818281 0.0339049985250659 0.0348579473727495"
        rpy="0 0 0" />
      <mass
        value="0.195948164366842" />
      <inertia
        ixx="0.000268712104683053"
        ixy="7.0760744892282E-06"
        ixz="1.63455208337381E-07"
        iyy="5.50524997357663E-05"
        iyz="-5.13468517837509E-06"
        izz="0.000281325428190112" />
    </inertial>
    <visual>
      <origin
        xyz="0 0 0"
        rpy="0 0 0" />
      <geometry>
        <mesh
          filename="package://5DOFArm/meshes/Motor4.STL" />
      </geometry>
      <material
        name="">
        <color
          rgba="0.752941176470588 0.752941176470588 0.752941176470588 1" />
      </material>
    </visual>
    <collision>
      <origin
        xyz="0 0 0"
        rpy="0 0 0" />
      <geometry>
        <mesh
          filename="package://5DOFArm/meshes/Motor4.STL" />
      </geometry>
    </collision>
  </link>
  <joint
    name="ConnectingJointB2"
    type="continuous">
    <origin
      xyz="0.0042028 -0.0031745 0.033"
      rpy="0.0052871 0 0" />
    <parent
      link="ConnectingJointB" />
    <child
      link="Motor4" />
    <axis
      xyz="0 0 -1" />
  </joint>
  <link
    name="Motor5">
    <inertial>
      <origin
        xyz="0.102740842268571 0.0585298349975694 -0.039124811870007"
        rpy="0 0 0" />
      <mass
        value="0.195948164492237" />
      <inertia
        ixx="0.000268946195940572"
        ixy="6.73752126133203E-09"
        ixz="-1.37361629210317E-08"
        iyy="0.000281325428211118"
        iyz="5.13728178679393E-06"
        izz="5.48184085161642E-05" />
    </inertial>
    <visual>
      <origin
        xyz="0 0 0"
        rpy="0 0 0" />
      <geometry>
        <mesh
          filename="package://5DOFArm/meshes/Motor5.STL" />
      </geometry>
      <material
        name="">
        <color
          rgba="0.752941176470588 0.752941176470588 0.752941176470588 1" />
      </material>
    </visual>
    <collision>
      <origin
        xyz="0 0 0"
        rpy="0 0 0" />
      <geometry>
        <mesh
          filename="package://5DOFArm/meshes/Motor5.STL" />
      </geometry>
    </collision>
  </link>
  <joint
    name="Motor4to5"
    type="fixed">
    <origin
      xyz="-0.10483 0.061156 0.10803"
      rpy="0 0 0.033134" />
    <parent
      link="Motor4" />
    <child
      link="Motor5" />
    <axis
      xyz="0 0 0" />
  </joint>
  <link
    name="Grapper">
    <inertial>
      <origin
        xyz="1.20240172973851E-06 0.145165293943956 0.00191044941687646"
        rpy="0 0 0" />
      <mass
        value="0.533035535630649" />
      <inertia
        ixx="0.000821014385608279"
        ixy="-1.01680436314611E-08"
        ixz="-1.9454749724721E-09"
        iyy="0.000472118630732692"
        iyz="-1.80227099416518E-06"
        izz="0.000880978619783394" />
    </inertial>
    <visual>
      <origin
        xyz="0 0 0"
        rpy="0 0 0" />
      <geometry>
        <mesh
          filename="package://5DOFArm/meshes/Grapper.STL" />
      </geometry>
      <material
        name="">
        <color
          rgba="0.752941176470588 0.752941176470588 0.752941176470588 1" />
      </material>
    </visual>
    <collision>
      <origin
        xyz="0 0 0"
        rpy="0 0 0" />
      <geometry>
        <mesh
          filename="package://5DOFArm/meshes/Grapper.STL" />
      </geometry>
    </collision>
  </link>
  <joint
    name="Motor5toGrapper"
    type="continuous">
    <origin
      xyz="0.10275 0.081137 -0.073049"
      rpy="0 -0.21955 0" />
    <parent
      link="Motor5" />
    <child
      link="Grapper" />
    <axis
      xyz="0 -1 0" />
  </joint>
</robot>